2023-01-19 12:23:00,172 INFO: Microblog startup [in /Users/cassiano/code/Python/flask_tutorial/app/__init__.py:43]
2023-01-19 12:23:04,474 ERROR: Exception on /user/Cassiano [GET] [in /Users/cassiano/code/Python/flask_tutorial/venv/lib/python3.9/site-packages/flask/app.py:1741]
Traceback (most recent call last):
  File "/Users/cassiano/code/Python/flask_tutorial/venv/lib/python3.9/site-packages/flask/app.py", line 2525, in wsgi_app
    response = self.full_dispatch_request()
  File "/Users/cassiano/code/Python/flask_tutorial/venv/lib/python3.9/site-packages/flask/app.py", line 1822, in full_dispatch_request
    rv = self.handle_user_exception(e)
  File "/Users/cassiano/code/Python/flask_tutorial/venv/lib/python3.9/site-packages/flask/app.py", line 1820, in full_dispatch_request
    rv = self.dispatch_request()
  File "/Users/cassiano/code/Python/flask_tutorial/venv/lib/python3.9/site-packages/flask/app.py", line 1796, in dispatch_request
    return self.ensure_sync(self.view_functions[rule.endpoint])(**view_args)
  File "/Users/cassiano/code/Python/flask_tutorial/venv/lib/python3.9/site-packages/flask_login/utils.py", line 290, in decorated_view
    return current_app.ensure_sync(func)(*args, **kwargs)
  File "/Users/cassiano/code/Python/flask_tutorial/app/routes.py", line 69, in user
    return render_template('user.html', user=user, posts=posts)
  File "/Users/cassiano/code/Python/flask_tutorial/venv/lib/python3.9/site-packages/flask/templating.py", line 146, in render_template
    template = app.jinja_env.get_or_select_template(template_name_or_list)
  File "/Users/cassiano/code/Python/flask_tutorial/venv/lib/python3.9/site-packages/jinja2/environment.py", line 1081, in get_or_select_template
    return self.get_template(template_name_or_list, parent, globals)
  File "/Users/cassiano/code/Python/flask_tutorial/venv/lib/python3.9/site-packages/jinja2/environment.py", line 1010, in get_template
    return self._load_template(name, globals)
  File "/Users/cassiano/code/Python/flask_tutorial/venv/lib/python3.9/site-packages/jinja2/environment.py", line 969, in _load_template
    template = self.loader.load(self, name, self.make_globals(globals))
  File "/Users/cassiano/code/Python/flask_tutorial/venv/lib/python3.9/site-packages/jinja2/loaders.py", line 138, in load
    code = environment.compile(source, name, filename)
  File "/Users/cassiano/code/Python/flask_tutorial/venv/lib/python3.9/site-packages/jinja2/environment.py", line 768, in compile
    self.handle_exception(source=source_hint)
  File "/Users/cassiano/code/Python/flask_tutorial/venv/lib/python3.9/site-packages/jinja2/environment.py", line 936, in handle_exception
    raise rewrite_traceback_stack(source=source)
  File "/Users/cassiano/code/Python/flask_tutorial/app/templates/user.html", line 11, in template
    {% endi %} {% if user == current_user %}
jinja2.exceptions.TemplateSyntaxError: Encountered unknown tag 'endi'. Jinja was looking for the following tags: 'elif' or 'else' or 'endif'. The innermost block that needs to be closed is 'if'.
2023-01-19 12:29:14,956 ERROR: Exception on /edit_profile [POST] [in /Users/cassiano/code/Python/flask_tutorial/venv/lib/python3.9/site-packages/flask/app.py:1741]
Traceback (most recent call last):
  File "/Users/cassiano/code/Python/flask_tutorial/venv/lib/python3.9/site-packages/sqlalchemy/engine/base.py", line 1900, in _execute_context
    self.dialect.do_execute(
  File "/Users/cassiano/code/Python/flask_tutorial/venv/lib/python3.9/site-packages/sqlalchemy/engine/default.py", line 736, in do_execute
    cursor.execute(statement, parameters)
sqlite3.IntegrityError: UNIQUE constraint failed: user.username

The above exception was the direct cause of the following exception:

Traceback (most recent call last):
  File "/Users/cassiano/code/Python/flask_tutorial/venv/lib/python3.9/site-packages/flask/app.py", line 2525, in wsgi_app
    response = self.full_dispatch_request()
  File "/Users/cassiano/code/Python/flask_tutorial/venv/lib/python3.9/site-packages/flask/app.py", line 1822, in full_dispatch_request
    rv = self.handle_user_exception(e)
  File "/Users/cassiano/code/Python/flask_tutorial/venv/lib/python3.9/site-packages/flask/app.py", line 1820, in full_dispatch_request
    rv = self.dispatch_request()
  File "/Users/cassiano/code/Python/flask_tutorial/venv/lib/python3.9/site-packages/flask/app.py", line 1796, in dispatch_request
    return self.ensure_sync(self.view_functions[rule.endpoint])(**view_args)
  File "/Users/cassiano/code/Python/flask_tutorial/venv/lib/python3.9/site-packages/flask_login/utils.py", line 290, in decorated_view
    return current_app.ensure_sync(func)(*args, **kwargs)
  File "/Users/cassiano/code/Python/flask_tutorial/app/routes.py", line 86, in edit_profile
    db.session.commit()
  File "<string>", line 2, in commit
  File "/Users/cassiano/code/Python/flask_tutorial/venv/lib/python3.9/site-packages/sqlalchemy/orm/session.py", line 1451, in commit
    self._transaction.commit(_to_root=self.future)
  File "/Users/cassiano/code/Python/flask_tutorial/venv/lib/python3.9/site-packages/sqlalchemy/orm/session.py", line 829, in commit
    self._prepare_impl()
  File "/Users/cassiano/code/Python/flask_tutorial/venv/lib/python3.9/site-packages/sqlalchemy/orm/session.py", line 808, in _prepare_impl
    self.session.flush()
  File "/Users/cassiano/code/Python/flask_tutorial/venv/lib/python3.9/site-packages/sqlalchemy/orm/session.py", line 3444, in flush
    self._flush(objects)
  File "/Users/cassiano/code/Python/flask_tutorial/venv/lib/python3.9/site-packages/sqlalchemy/orm/session.py", line 3584, in _flush
    transaction.rollback(_capture_exception=True)
  File "/Users/cassiano/code/Python/flask_tutorial/venv/lib/python3.9/site-packages/sqlalchemy/util/langhelpers.py", line 70, in __exit__
    compat.raise_(
  File "/Users/cassiano/code/Python/flask_tutorial/venv/lib/python3.9/site-packages/sqlalchemy/util/compat.py", line 211, in raise_
    raise exception
  File "/Users/cassiano/code/Python/flask_tutorial/venv/lib/python3.9/site-packages/sqlalchemy/orm/session.py", line 3544, in _flush
    flush_context.execute()
  File "/Users/cassiano/code/Python/flask_tutorial/venv/lib/python3.9/site-packages/sqlalchemy/orm/unitofwork.py", line 456, in execute
    rec.execute(self)
  File "/Users/cassiano/code/Python/flask_tutorial/venv/lib/python3.9/site-packages/sqlalchemy/orm/unitofwork.py", line 630, in execute
    util.preloaded.orm_persistence.save_obj(
  File "/Users/cassiano/code/Python/flask_tutorial/venv/lib/python3.9/site-packages/sqlalchemy/orm/persistence.py", line 237, in save_obj
    _emit_update_statements(
  File "/Users/cassiano/code/Python/flask_tutorial/venv/lib/python3.9/site-packages/sqlalchemy/orm/persistence.py", line 1001, in _emit_update_statements
    c = connection._execute_20(
  File "/Users/cassiano/code/Python/flask_tutorial/venv/lib/python3.9/site-packages/sqlalchemy/engine/base.py", line 1705, in _execute_20
    return meth(self, args_10style, kwargs_10style, execution_options)
  File "/Users/cassiano/code/Python/flask_tutorial/venv/lib/python3.9/site-packages/sqlalchemy/sql/elements.py", line 334, in _execute_on_connection
    return connection._execute_clauseelement(
  File "/Users/cassiano/code/Python/flask_tutorial/venv/lib/python3.9/site-packages/sqlalchemy/engine/base.py", line 1572, in _execute_clauseelement
    ret = self._execute_context(
  File "/Users/cassiano/code/Python/flask_tutorial/venv/lib/python3.9/site-packages/sqlalchemy/engine/base.py", line 1943, in _execute_context
    self._handle_dbapi_exception(
  File "/Users/cassiano/code/Python/flask_tutorial/venv/lib/python3.9/site-packages/sqlalchemy/engine/base.py", line 2124, in _handle_dbapi_exception
    util.raise_(
  File "/Users/cassiano/code/Python/flask_tutorial/venv/lib/python3.9/site-packages/sqlalchemy/util/compat.py", line 211, in raise_
    raise exception
  File "/Users/cassiano/code/Python/flask_tutorial/venv/lib/python3.9/site-packages/sqlalchemy/engine/base.py", line 1900, in _execute_context
    self.dialect.do_execute(
  File "/Users/cassiano/code/Python/flask_tutorial/venv/lib/python3.9/site-packages/sqlalchemy/engine/default.py", line 736, in do_execute
    cursor.execute(statement, parameters)
sqlalchemy.exc.IntegrityError: (sqlite3.IntegrityError) UNIQUE constraint failed: user.username
[SQL: UPDATE user SET username=?, about_me=? WHERE user.id = ?]
[parameters: ('cassiano', '', 5)]
(Background on this error at: https://sqlalche.me/e/14/gkpj)
