2023-01-23 11:09:50,519 ERROR: Exception on /user/Cassiano [GET] [in /Users/cassiano/code/Python/flask_tutorial/venv/lib/python3.9/site-packages/flask/app.py:1741]
Traceback (most recent call last):
  File "/Users/cassiano/code/Python/flask_tutorial/venv/lib/python3.9/site-packages/flask/app.py", line 2525, in wsgi_app
    response = self.full_dispatch_request()
  File "/Users/cassiano/code/Python/flask_tutorial/venv/lib/python3.9/site-packages/flask/app.py", line 1822, in full_dispatch_request
    rv = self.handle_user_exception(e)
  File "/Users/cassiano/code/Python/flask_tutorial/venv/lib/python3.9/site-packages/flask/app.py", line 1820, in full_dispatch_request
    rv = self.dispatch_request()
  File "/Users/cassiano/code/Python/flask_tutorial/venv/lib/python3.9/site-packages/flask/app.py", line 1796, in dispatch_request
    return self.ensure_sync(self.view_functions[rule.endpoint])(**view_args)
  File "/Users/cassiano/code/Python/flask_tutorial/venv/lib/python3.9/site-packages/flask_login/utils.py", line 290, in decorated_view
    return current_app.ensure_sync(func)(*args, **kwargs)
  File "/Users/cassiano/code/Python/flask_tutorial/app/routes.py", line 69, in user
    form = EmptyForm()
  File "/Users/cassiano/code/Python/flask_tutorial/venv/lib/python3.9/site-packages/flask/templating.py", line 147, in render_template
    return _render(app, template, context)
  File "/Users/cassiano/code/Python/flask_tutorial/venv/lib/python3.9/site-packages/flask/templating.py", line 130, in _render
    rv = template.render(context)
  File "/Users/cassiano/code/Python/flask_tutorial/venv/lib/python3.9/site-packages/jinja2/environment.py", line 1301, in render
    self.environment.handle_exception()
  File "/Users/cassiano/code/Python/flask_tutorial/venv/lib/python3.9/site-packages/jinja2/environment.py", line 936, in handle_exception
    raise rewrite_traceback_stack(source=source)
  File "/Users/cassiano/code/Python/flask_tutorial/app/templates/user.html", line 1, in top-level template code
    {% extends "base.html" %} {% block content %}
  File "/Users/cassiano/code/Python/flask_tutorial/app/templates/base.html", line 29, in top-level template code
    {% endif %} {% endwith %} {% block content %}{% endblock %}
  File "/Users/cassiano/code/Python/flask_tutorial/app/templates/user.html", line 12, in block 'content'
    <p>{{ user.follwers.count() }} followers, {{ user.followed.count() }} following.</p>
  File "/Users/cassiano/code/Python/flask_tutorial/venv/lib/python3.9/site-packages/jinja2/environment.py", line 485, in getattr
    return getattr(obj, attribute)
jinja2.exceptions.UndefinedError: 'app.models.User object' has no attribute 'follwers'
2023-01-23 11:12:26,946 ERROR: Exception on /user/Cassiano [GET] [in /Users/cassiano/code/Python/flask_tutorial/venv/lib/python3.9/site-packages/flask/app.py:1741]
Traceback (most recent call last):
  File "/Users/cassiano/code/Python/flask_tutorial/venv/lib/python3.9/site-packages/flask/app.py", line 2525, in wsgi_app
    response = self.full_dispatch_request()
  File "/Users/cassiano/code/Python/flask_tutorial/venv/lib/python3.9/site-packages/flask/app.py", line 1822, in full_dispatch_request
    rv = self.handle_user_exception(e)
  File "/Users/cassiano/code/Python/flask_tutorial/venv/lib/python3.9/site-packages/flask/app.py", line 1820, in full_dispatch_request
    rv = self.dispatch_request()
  File "/Users/cassiano/code/Python/flask_tutorial/venv/lib/python3.9/site-packages/flask/app.py", line 1796, in dispatch_request
    return self.ensure_sync(self.view_functions[rule.endpoint])(**view_args)
  File "/Users/cassiano/code/Python/flask_tutorial/venv/lib/python3.9/site-packages/flask_login/utils.py", line 290, in decorated_view
    return current_app.ensure_sync(func)(*args, **kwargs)
  File "/Users/cassiano/code/Python/flask_tutorial/app/routes.py", line 69, in user
    form = EmptyForm()
  File "/Users/cassiano/code/Python/flask_tutorial/venv/lib/python3.9/site-packages/flask/templating.py", line 147, in render_template
    return _render(app, template, context)
  File "/Users/cassiano/code/Python/flask_tutorial/venv/lib/python3.9/site-packages/flask/templating.py", line 130, in _render
    rv = template.render(context)
  File "/Users/cassiano/code/Python/flask_tutorial/venv/lib/python3.9/site-packages/jinja2/environment.py", line 1301, in render
    self.environment.handle_exception()
  File "/Users/cassiano/code/Python/flask_tutorial/venv/lib/python3.9/site-packages/jinja2/environment.py", line 936, in handle_exception
    raise rewrite_traceback_stack(source=source)
  File "/Users/cassiano/code/Python/flask_tutorial/app/templates/user.html", line 1, in top-level template code
    {% extends "base.html" %} {% block content %}
  File "/Users/cassiano/code/Python/flask_tutorial/app/templates/base.html", line 29, in top-level template code
    {% endif %} {% endwith %} {% block content %}{% endblock %}
  File "/Users/cassiano/code/Python/flask_tutorial/app/templates/user.html", line 12, in block 'content'
    {% if user == current_user %}
  File "/Users/cassiano/code/Python/flask_tutorial/venv/lib/python3.9/site-packages/jinja2/environment.py", line 485, in getattr
    return getattr(obj, attribute)
jinja2.exceptions.UndefinedError: 'app.models.User object' has no attribute 'follwers'
2023-01-23 11:14:45,426 ERROR: Exception on /user/Cassiano [GET] [in /Users/cassiano/code/Python/flask_tutorial/venv/lib/python3.9/site-packages/flask/app.py:1741]
Traceback (most recent call last):
  File "/Users/cassiano/code/Python/flask_tutorial/venv/lib/python3.9/site-packages/flask/app.py", line 2525, in wsgi_app
    response = self.full_dispatch_request()
  File "/Users/cassiano/code/Python/flask_tutorial/venv/lib/python3.9/site-packages/flask/app.py", line 1822, in full_dispatch_request
    rv = self.handle_user_exception(e)
  File "/Users/cassiano/code/Python/flask_tutorial/venv/lib/python3.9/site-packages/flask/app.py", line 1820, in full_dispatch_request
    rv = self.dispatch_request()
  File "/Users/cassiano/code/Python/flask_tutorial/venv/lib/python3.9/site-packages/flask/app.py", line 1796, in dispatch_request
    return self.ensure_sync(self.view_functions[rule.endpoint])(**view_args)
  File "/Users/cassiano/code/Python/flask_tutorial/venv/lib/python3.9/site-packages/flask_login/utils.py", line 290, in decorated_view
    return current_app.ensure_sync(func)(*args, **kwargs)
  File "/Users/cassiano/code/Python/flask_tutorial/app/routes.py", line 69, in user
    form = EmptyForm()
  File "/Users/cassiano/code/Python/flask_tutorial/venv/lib/python3.9/site-packages/flask/templating.py", line 147, in render_template
    return _render(app, template, context)
  File "/Users/cassiano/code/Python/flask_tutorial/venv/lib/python3.9/site-packages/flask/templating.py", line 130, in _render
    rv = template.render(context)
  File "/Users/cassiano/code/Python/flask_tutorial/venv/lib/python3.9/site-packages/jinja2/environment.py", line 1301, in render
    self.environment.handle_exception()
  File "/Users/cassiano/code/Python/flask_tutorial/venv/lib/python3.9/site-packages/jinja2/environment.py", line 936, in handle_exception
    raise rewrite_traceback_stack(source=source)
  File "/Users/cassiano/code/Python/flask_tutorial/app/templates/user.html", line 1, in top-level template code
    {% extends "base.html" %} {% block content %}
  File "/Users/cassiano/code/Python/flask_tutorial/app/templates/base.html", line 29, in top-level template code
    {% endif %} {% endwith %} {% block content %}{% endblock %}
  File "/Users/cassiano/code/Python/flask_tutorial/app/templates/user.html", line 12, in block 'content'
    {% if user == current_user %}
  File "/Users/cassiano/code/Python/flask_tutorial/venv/lib/python3.9/site-packages/jinja2/environment.py", line 485, in getattr
    return getattr(obj, attribute)
jinja2.exceptions.UndefinedError: 'app.models.User object' has no attribute 'follwers'
